<?xml version="1.0" ?>
<!-- =================================================================================== -->
<!-- |    This document was autogenerated by xacro from /catkin_ws/src/ros_tank/urdf/robot.xacro | -->
<!-- |    EDITING THIS FILE BY HAND IS NOT RECOMMENDED                                 | -->
<!-- =================================================================================== -->
<robot name="robot">
    <!-- Colors -->
    <gazebo reference="link_chassis">
        <material>Gazebo/Blue</material>
        <plugin name="gazebo_ros_control">
            <robotNamespace>/</robotNamespace>
        </plugin>
    </gazebo>
    <gazebo reference="link_front_left_wheel">
        <material>Gazebo/Black</material>
        <mu1>0</mu1>
        <mu2>0</mu2>
    </gazebo>
    <gazebo reference="link_rear_right_wheel">
        <material>Gazebo/Black</material>
        <mu1>0</mu1>
        <mu2>0</mu2>
    </gazebo>
    <gazebo reference="link_rear_left_wheel">
        <material>Gazebo/Black</material>
        <mu1>0</mu1>
        <mu2>0</mu2>
    </gazebo>
    <gazebo reference="link_front_right_wheel">
        <material>Gazebo/Black</material>
        <mu1>0</mu1>
        <mu2>0</mu2>
    </gazebo>
    <gazebo reference="link_middle_right_wheel">
        <material>Gazebo/Black</material>
        <mu1>0.1</mu1>
        <mu2>0.1</mu2>
    </gazebo>
    <gazebo reference="link_middle_left_wheel">
        <material>Gazebo/Black</material>
        <mu1>0.1</mu1>
        <mu2>0.1</mu2>
    </gazebo>
    <!-- Gazebo tags - Laser scan -->
    <gazebo reference="joint_laser_scan_chassis">
        <preserveFixedJoint>true</preserveFixedJoint>
    </gazebo>
    <gazebo reference="link_laser_scan">
        <material>Gazebo/DarkGrey</material>
    </gazebo>
    <!-- <gazebo reference="joint_chassis_left_front_wheel">
        <preserveFixedJoint>true</preserveFixedJoint>
    </gazebo>
    <gazebo reference="joint_chassis_left_rear_wheel">
        <preserveFixedJoint>true</preserveFixedJoint>
    </gazebo>
    <gazebo reference="joint_chassis_right_front_wheel">
        <preserveFixedJoint>true</preserveFixedJoint>
    </gazebo>
    <gazebo reference="joint_chassis_right_rear_wheel">
        <preserveFixedJoint>true</preserveFixedJoint>
    </gazebo>  
     -->
    <gazebo reference="link_laser_scan">
        <sensor name="head_hokuyo_sensor" type="ray">
            <pose>0 0 0 0 0 0</pose>
            <visualize>true</visualize>
            <update_rate>20</update_rate>
            <ray>
                <scan>
                    <horizontal>
                        <samples>720</samples>
                        <resolution>1</resolution>
                        <min_angle>-3.14</min_angle>
                        <max_angle>3.14</max_angle>
                    </horizontal>
                </scan>
                <range>
                    <min>0.20</min>
                    <max>12.0</max>
                    <resolution>0.01</resolution>
                </range>
                <noise>
                    <type>gaussian</type>
                    <mean>0.0</mean>
                    <stddev>0.01</stddev>
                </noise>
            </ray>
            <plugin filename="libgazebo_ros_laser.so" name="gazebo_ros_head_hokuyo_controller">
                <topicName>/laser/scan</topicName>
                <frameName>link_chassis</frameName>
            </plugin>
        </sensor>
    </gazebo>
    <!-- camera -->
    <gazebo reference="camera_link">
        <sensor name="camera_robot" type="camera">
            <camera>
                <pose>0 0 0 0 0 0</pose>
                <visualize>true</visualize>
                <update_rate>10</update_rate>
                <horizontal_fov>1.089</horizontal_fov>
                <image>
                    <format>R8G8B8</format>
                    <width>640</width>
                    <height>480</height>
                </image>
                <noise>
                    <type>gaussian</type>
                    <mean>0.0</mean>
                    <stddev>0.007</stddev>
                </noise>
            </camera>
            <plugin filename="libgazebo_ros_camera.so" name="camera_controller">
                <alwaysOn>true</alwaysOn>
                <updateRate>0.0</updateRate>
                <imageTopicName>image_raw</imageTopicName>
                <cameraName>camera</cameraName>
                <cameraInfoTopicName>camera_info</cameraInfoTopicName>
                <frameName>link_chassis</frameName>
            </plugin>
        </sensor>
    </gazebo>
    <gazebo>
        <plugin filename="libgazebo_ros_diff_drive.so" name="differential_drive_controller">
            <alwaysOn>true</alwaysOn>
            <updateRate>20</updateRate>
            <leftJoint>joint_chassis_left_middle_wheel</leftJoint>
            <rightJoint>joint_chassis_right_middle_wheel</rightJoint>
            <wheelSeparation>0.14</wheelSeparation>
            <wheelDiameter>0.04</wheelDiameter>
            <torque>10</torque>
            <wheelTorque>5</wheelTorque>
            <commandTopic>cmd_vel</commandTopic>
            <odometryTopic>odom</odometryTopic>
            <odometryFrame>odom</odometryFrame>
            <robotBaseFrame>link_chassis</robotBaseFrame>
            <publishWheelTF>false</publishWheelTF>
            <publishWheelJointState>false</publishWheelJointState>
            <publishOdomTF>true</publishOdomTF>
            <wheelAcceleration>0</wheelAcceleration>
            <rosDebugLevel>na</rosDebugLevel>
            <odometrySource>world</odometrySource>
            <publishTf>1</publishTf>
        </plugin>
    </gazebo>
    <link name="world" />
    <joint name="joint_world" type="fixed">
        <origin rpy="0 0 0" xyz="0 0 0" />
        <child link="link_chassis" />
        <parent link="world" />
    </joint>
    <!-- Laser scan -->
    <joint name="joint_laser_scan_chassis" type="fixed">
        <origin rpy="0 0 0" xyz="-0.01 0 0.11" />
        <child link="link_laser_scan" />
        <parent link="link_chassis" />
        <joint_properties damping="1.0" friction="1.0" />
    </joint>
    <link name="link_laser_scan">
        <inertial>
            <origin rpy="0 0 0" xyz="0 0 0" />
            <mass value="0.5" />
            <inertia ixx="0.000252666666667" ixy="0" ixz="0" iyy="0.000252666666667" iyz="0" izz="0.0005" />
        </inertial>
        <visual>
            <origin rpy="0 0 0" xyz="0 0 0" />
            <geometry>
                <mesh filename="package://ros_tank/meshes/lidarA1.stl" pose="0 0 0" scale="0.00111 0.00111 0.0011" />
                <!-- <cylinder radius="0.04" length="0.04"/> -->
            </geometry>
            <material name="Red">
                <color rgba="0.7 0.1 0.1 1" />
            </material>
        </visual>
        <collision>
            <origin rpy="0 0 0" xyz="0 0 0" />
            <geometry>
                <cylinder length="0.04" radius="0.04" />
            </geometry>
        </collision>
    </link>
    <!-- Camera -->
    <joint name="camera_joint" type="fixed">
        <parent link="camera_second_servo_link" />
        <child link="camera_link" />
        <origin rpy="0 0 0" xyz="0.03 0 0.017" />
    </joint>
    <link name="camera_link">
        <collision>
            <origin rpy="0 0 0" xyz="0 0 0" />
            <geometry>
                <box size="0.02 0.08 0.038" />
            </geometry>
        </collision>
        <visual>
            <geometry>
                <mesh filename="package://ros_tank/meshes/camera.stl" pose="0 0 0" scale="0.00111 0.00111 0.0011" />
                <!-- <box size="0.02 0.08 0.038"/> -->
            </geometry>
        </visual>
        <inertial>
            <mass value="0.1" />
            <origin xyz="0 0 0" rpy="0 0 0" />
            <inertia ixx="0.03" iyy="0.03" izz="0.03" ixy="0.0" ixz="0.0" iyz="0.0" />
        </inertial>
    </link>
    <!-- Link - chassis -->
    <link name="link_chassis">
        <collision>
            <origin rpy="0 0 0" xyz="0 0 -0.08" />
            <geometry>
                <box size="0.25 0.25 0.1" />
            </geometry>
        </collision>
        <visual>
            <geometry>
                <!-- <box size="0.22 0.14 0.25" /> -->
                <mesh filename="package://ros_tank/meshes/tank_body.stl" pose="0 0 0" scale="0.00111 0.00111 0.0011" />
            </geometry>
            <material name="Red">
                <color rgba="1 0 0 1" />
            </material>
        </visual>
        <inertial>
            <mass value="0.1" />
            <origin xyz="0 0 0" rpy="0 0 0" />
            <inertia ixx="0.03" iyy="0.03" izz="0.03" ixy="0.0" ixz="0.0" iyz="0.0" />
        </inertial>
    </link>
    <!-- Joint - chassis / left front wheel -->
    <joint name="joint_chassis_left_front_wheel" type="fixed">
        <origin rpy="0 0 0" xyz="0.065 0.077 -0.12" />
        <child link="link_front_left_wheel" />
        <parent link="link_chassis" />
        <axis rpy="0 0 0" xyz="0 1 0" />
        <limit effort="10000" velocity="1000" />
        <joint_properties damping="1.0" friction="1.0" />
    </joint>
    <!-- Link - left front wheel -->
    <link name="link_front_left_wheel">
        <inertial>
            <mass value="10" />
            <origin rpy="0 0 0" xyz="0 0 0.3" />
            <inertia ixx="1.5417" ixy="0" ixz="0" iyy="3.467" iyz="0" izz="4.742" />
        </inertial>
        <collision>
            <origin rpy="1.5707 0 0" xyz="0 -0.015 0" />
            <geometry>
                <cylinder length="0.03" radius="0.02" />
            </geometry>
        </collision>
        <visual>
            <origin rpy="1.5707 0 0" xyz="0 0.015 0" />
            <geometry>
                <cylinder length="0.03" radius="0.02" />
            </geometry>
        </visual>
    </link>
    <!-- Joint - chassis / left middle wheel -->
    <joint name="joint_chassis_left_middle_wheel" type="continuous">
        <origin rpy="0 0 0" xyz="0 0.077 -0.12" />
        <child link="link_middle_left_wheel" />
        <parent link="link_chassis" />
        <axis rpy="0 0 0" xyz="0 1 0" />
        <limit effort="10000" velocity="1000" />
        <joint_properties damping="1.0" friction="1.0" />
    </joint>
    <!-- Link - left middle wheel -->
    <link name="link_middle_left_wheel">
        <inertial>
            <mass value="10" />
            <origin rpy="0 0 0" xyz="0 0 0.3" />
            <inertia ixx="1.5417" ixy="0" ixz="0" iyy="3.467" iyz="0" izz="4.742" />
        </inertial>
        <collision>
            <origin rpy="1.5707 0 0" xyz="0 0.015 0" />
            <geometry>
                <cylinder length="0.03" radius="0.02" />
            </geometry>
        </collision>
        <visual>
            <origin rpy="1.5707 0 0" xyz="0 0.015 0" />
            <geometry>
                <cylinder length="0.03" radius="0.02" />
            </geometry>
        </visual>
    </link>
    <!-- Joint - chassis / left rear wheel -->
    <joint name="joint_chassis_left_rear_wheel" type="fixed">
        <origin rpy="0 0 0" xyz="-0.065 0.077 -0.12" />
        <child link="link_rear_left_wheel" />
        <parent link="link_chassis" />
        <axis rpy="0 0 0" xyz="0 1 0" />
        <limit effort="10000" velocity="1000" />
        <joint_properties damping="1.0" friction="1.0" />
    </joint>
    <!-- Link - left rear wheel -->
    <link name="link_rear_left_wheel">
        <inertial>
            <mass value="10" />
            <origin rpy="0 0 0" xyz="0 0 0.3" />
            <inertia ixx="1.5417" ixy="0" ixz="0" iyy="3.467" iyz="0" izz="4.742" />
        </inertial>
        <collision>
            <origin rpy="1.5707 0 0" xyz="0 0.015 0" />
            <geometry>
                <cylinder length="0.03" radius="0.02" />
            </geometry>
        </collision>
        <visual>
            <origin rpy="1.5707 0 0" xyz="0 0.015 0" />
            <geometry>
                <cylinder length="0.03" radius="0.02" />
            </geometry>
        </visual>
    </link>
    <!-- Joint - chassis / right front wheel -->
    <joint name="joint_chassis_right_front_wheel" type="fixed">
        <origin rpy="0 0 0" xyz="0.065 -0.077 -0.12" />
        <child link="link_front_right_wheel" />
        <parent link="link_chassis" />
        <axis rpy="0 0 0" xyz="0 1 0" />
        <limit effort="10000" velocity="1000" />
        <joint_properties damping="1.0" friction="1.0" />
    </joint>
    <!-- Link - right front wheel -->
    <link name="link_front_right_wheel">
        <inertial>
            <mass value="10" />
            <origin rpy="0 0 0" xyz="0 0 0.3" />
            <inertia ixx="1.5417" ixy="0" ixz="0" iyy="3.467" iyz="0" izz="4.742" />
        </inertial>
        <collision>
            <origin rpy="1.5707 0 0" xyz="0 -0.015 0" />
            <geometry>
                <cylinder length="0.03" radius="0.02" />
            </geometry>
        </collision>
        <visual>
            <origin rpy="1.5707 0 0" xyz="0 -0.015 0" />
            <geometry>
                <cylinder length="0.03" radius="0.02" />
            </geometry>
        </visual>
    </link>
    <!-- Joint - chassis / right middle wheel -->
    <joint name="joint_chassis_right_middle_wheel" type="continuous">
        <origin rpy="0 0 0" xyz="0 -0.077 -0.12" />
        <child link="link_middle_right_wheel" />
        <parent link="link_chassis" />
        <axis rpy="0 0 0" xyz="0 1 0" />
        <limit effort="10000" velocity="1000" />
        <joint_properties damping="1.0" friction="1.0" />
    </joint>
    <!-- Link - right middle wheel -->
    <link name="link_middle_right_wheel">
        <inertial>
            <mass value="10" />
            <origin rpy="0 0 0" xyz="0 0 0.3" />
            <inertia ixx="1.5417" ixy="0" ixz="0" iyy="3.467" iyz="0" izz="4.742" />
        </inertial>
        <collision>
            <origin rpy="1.5707 0 0" xyz="0 -0.015 0" />
            <geometry>
                <cylinder length="0.03" radius="0.02" />
            </geometry>
        </collision>
        <visual>
            <origin rpy="1.5707 0 0" xyz="0 -0.015 0" />
            <geometry>
                <cylinder length="0.03" radius="0.02" />
            </geometry>
        </visual>
    </link>
    <!-- Joint - chassis / right rear wheel -->
    <joint name="joint_chassis_right_rear_wheel" type="fixed">
        <origin rpy="0 0 0" xyz="-0.065 -0.077 -0.12" />
        <child link="link_rear_right_wheel" />
        <parent link="link_chassis" />
        <axis rpy="0 0 0" xyz="0 1 0" />
        <limit effort="10000" velocity="1000" />
        <joint_properties damping="1.0" friction="1.0" />
    </joint>
    <!-- Link - right rear wheel -->
    <link name="link_rear_right_wheel">
        <inertial>
            <mass value="10" />
            <origin rpy="0 0 0" xyz="0 0 0.3" />
            <inertia ixx="1.5417" ixy="0" ixz="0" iyy="3.467" iyz="0" izz="4.742" />
        </inertial>
        <collision>
            <origin rpy="1.5707 0 0" xyz="0 -0.015 0" />
            <geometry>
                <cylinder length="0.03" radius="0.02" />
            </geometry>
        </collision>
        <visual>
            <origin rpy="1.5707 0 0" xyz="0 -0.015 0" />
            <geometry>
                <cylinder length="0.03" radius="0.02" />
            </geometry>
        </visual>
    </link>
    <!-- Joint - camera second servo -->
    <joint name="camera_servo_second_joint" type="revolute">
        <origin rpy="0 0 0" xyz="0.03 -0.005 0.02" />
        <parent link="camera_servo_first_link" />
        <child link="camera_second_servo_link" />
        <axis xyz="0 1 0" />
        <limit effort="100" lower="-1.15" upper="1.4" velocity="100" />
    </joint>
    <!-- Link - camera second servo -->
    <link name="camera_second_servo_link">
        <collision>
            <origin rpy="0 0 0" xyz="0 0 0.01" />
            <geometry>
                <box size="0.02 0.03 0.03" />
            </geometry>
        </collision>
        <visual>
            <origin rpy="0 0 0" xyz="0 0 0" />
            <geometry>
                <!-- <box size="0.02 0.03 0.03" /> -->
                <mesh filename="package://ros_tank/meshes/camera_servo_2.stl" pose="0 0 0" scale="0.0011 0.00111 0.0011" />
            </geometry>
            <material name="orange" />
        </visual>
        <inertial>
            <mass value="0.1" />
            <origin xyz="0 0 0" rpy="0 0 0" />
            <inertia ixx="0.03" iyy="0.03" izz="0.03" ixy="0.0" ixz="0.0" iyz="0.0" />
        </inertial>
    </link>
    <!-- Joint - camera first servo -->
    <joint name="camera_servo_first_joint" type="revolute">
        <origin rpy="0 0 0" xyz="0.053 0 0" />
        <parent link="link_chassis" />
        <child link="camera_servo_first_link" />
        <axis xyz="0 0 1" />
        <limit effort="100" lower="-1.15" upper="1.4" velocity="100" />
    </joint>
    <!-- Link - camera first servo -->
    <link name="camera_servo_first_link">
        <collision>
            <origin rpy="0 0 0" xyz="0 0 -0.005" />
            <geometry>
                <box size="0.03 0.04 0.03" />
            </geometry>
        </collision>
        <visual>
            <origin rpy="0 0 0" xyz="0 0 0" />
            <geometry>
                <mesh filename="package://ros_tank/meshes/camera_servo_1.stl" pose="0 0 0" scale="0.0011 0.00111 0.0011" />
                <!-- <box size="0.03 0.04 0.05" /> -->
            </geometry>
            <material name="orange" />
        </visual>
        <inertial>
            <mass value="0.1" />
            <origin xyz="0 0 0" rpy="0 0 0" />
            <inertia ixx="0.03" iyy="0.03" izz="0.03" ixy="0.0" ixz="0.0" iyz="0.0" />
        </inertial>
    </link>
    <transmission name="trans_joint_chassis_left_middle_wheel">
        <type>transmission_interface/SimpleTransmission</type>
        <joint name="joint_chassis_left_middle_wheel">
            <hardwareInterface>hardware_interface/EffortJointInterface</hardwareInterface>
        </joint>
        <actuator name="joint_chassis_left_middle_wheel_motor">
            <hardwareInterface>hardware_interface/EffortJointInterface</hardwareInterface>
            <mechanicalReduction>1</mechanicalReduction>
        </actuator>
    </transmission>
    <transmission name="trans_joint_chassis_right_middle_wheel">
        <type>transmission_interface/SimpleTransmission</type>
        <joint name="joint_chassis_right_middle_wheel">
            <hardwareInterface>hardware_interface/EffortJointInterface</hardwareInterface>
        </joint>
        <actuator name="joint_chassis_right_middle_wheel_motor">
            <hardwareInterface>hardware_interface/EffortJointInterface</hardwareInterface>
            <mechanicalReduction>1</mechanicalReduction>
        </actuator>
    </transmission>
    <transmission name="trans_camera_servo_second_joint">
        <type>transmission_interface/SimpleTransmission</type>
        <joint name="camera_servo_second_joint">
            <hardwareInterface>hardware_interface/EffortJointInterface</hardwareInterface>
        </joint>
        <actuator name="camera_servo_second_joint_motor">
            <hardwareInterface>hardware_interface/EffortJointInterface</hardwareInterface>
            <mechanicalReduction>1</mechanicalReduction>
        </actuator>
    </transmission>
    <transmission name="trans_camera_servo_first_joint">
        <type>transmission_interface/SimpleTransmission</type>
        <joint name="camera_servo_first_joint">
            <hardwareInterface>hardware_interface/EffortJointInterface</hardwareInterface>
        </joint>
        <actuator name="camera_servo_first_joint_motor">
            <hardwareInterface>hardware_interface/EffortJointInterface</hardwareInterface>
            <mechanicalReduction>1</mechanicalReduction>
        </actuator>
    </transmission>
</robot>

