<?xml version="1.0" ?>
<robot name="robot" xmlns:xacro="http://www.ros.org/wiki/xacro">
     <!-- Colors -->
    <gazebo reference="link_chassis">
        <material>Gazebo/Blue</material>
    </gazebo>
    <gazebo reference="link_left_back_wheel">
        <material>Gazebo/Black</material>
        <mu1>0.1</mu1>
        <mu2>0.1</mu2>
    </gazebo>
    <gazebo reference="link_right_back_wheel">
        <material>Gazebo/Black</material>
        <mu1>0.1</mu1>
        <mu2>0.1</mu2>
    </gazebo>
    <gazebo reference="link_left_front_wheel">
        <material>Gazebo/Black</material>
        <mu1>0</mu1>
        <mu2>0</mu2>
    </gazebo>
    <gazebo reference="link_right_front_wheel">
        <material>Gazebo/Black</material>
        <mu1>0</mu1>
        <mu2>0</mu2>
    </gazebo>

    <!-- Parameters -->
    <xacro:property name="chassis_mass" value="10" />

    <xacro:property name="radius_wheel" value="0.15" />
    <xacro:property name="length_wheel" value="0.06" />

    <xacro:property name="radius_cylinder_wheel" value="0.04" />
    <xacro:property name="length_cylinder_wheel" value="0.06" />
    <gazebo>
        <plugin filename="libgazebo_ros_diff_drive.so" name="differential_drive_controller">
            <alwaysOn>true</alwaysOn>
            <updateRate>30</updateRate>
            <leftJoint>joint_chassis_left_back_wheel</leftJoint>
            <rightJoint>joint_chassis_right_back_wheel</rightJoint>
            <wheelSeparation>0.6</wheelSeparation>
            <wheelDiameter>0.3</wheelDiameter>
            <torque>10</torque>
            <commandTopic>cmd_vel</commandTopic>
            <odometryTopic>odom</odometryTopic>
            <odometryFrame>odom</odometryFrame>
            <robotBaseFrame>link_chassis</robotBaseFrame>
        </plugin>
    </gazebo>

    <!-- Gazebo tags - Laser scan -->
    <gazebo reference="joint_laser_scan_chassis">
        <preserveFixedJoint>true</preserveFixedJoint>
    </gazebo>
    <gazebo reference="link_laser_scan">
        <material>Gazebo/DarkGrey</material>
    </gazebo>

    <gazebo reference="link_laser_scan">
        <sensor type="ray" name="head_hokuyo_sensor">
            <pose>0 0 0 0 0 0</pose>
            <visualize>true</visualize>
            <update_rate>20</update_rate>
            <ray>
                <scan>
                    <horizontal>
                        <samples>720</samples>
                        <resolution>1</resolution>
                        <min_angle>-3.14</min_angle>
                        <max_angle>3.14</max_angle>
                    </horizontal>
                </scan>
                <range>
                    <min>0.20</min>
                    <max>12.0</max>
                    <resolution>0.01</resolution>
                </range>
                <noise>
                    <type>gaussian</type>
                    <mean>0.0</mean>
                    <stddev>0.01</stddev>
                </noise>
            </ray>
            <plugin name="gazebo_ros_head_hokuyo_controller" filename="libgazebo_ros_laser.so">
                <topicName>/laser/scan</topicName>
                <frameName>link_chassis</frameName>
            </plugin>
        </sensor>
    </gazebo>

    <gazebo reference="camera_link">
        <sensor name="camera" type="camera">
            <camera>
                <pose> 0 0 0 0 0 0 </pose>
                <visualize>true</visualize>
                <update_rate>10</update_rate>
                <horizontal_fov>1.089</horizontal_fov>
                <image>
                    <format>R8G8B8</format>
                    <width>640</width>
                    <height>480</height>
                </image>
                <clip>
                    <near>0.05</near>
                    <far>30.0</far>
                </clip>
            </camera>
            <plugin name="camera_controller" filename="libgazebo_ros_camera.so">
                <frame_name>camera_link_optical</frame_name>
            </plugin>
        </sensor>
    </gazebo>

    <!-- Gazebo tags - Laser scan -->
    <gazebo reference="joint_laser_scan_chassis">
        <preserveFixedJoint>true</preserveFixedJoint>
    </gazebo>
    <gazebo reference="link_laser_scan">
        <material>Gazebo/DarkGrey</material>
    </gazebo>

    <!-- Link - chassis -->
    <link name="link_chassis">
        <inertial>
            <mass value="10" />
            <origin xyz="0 0 0.3" rpy="0 0 0" />
            <inertia ixx="1.5417" ixy="0" ixz="0" iyy="3.467" iyz="0" izz="4.742" />
        </inertial>

        <collision>
            <geometry>
                <box size="1 0.6 0.2" />
            </geometry>
        </collision>

        <visual>
            <geometry>
                <box size="1 0.6 0.2" />
            </geometry>
            <material name="DarkBlue">
                <color rgba="0.2 0.2 0.4 1" />
            </material>
        </visual>
    </link>

    <joint name="joint_chassis_left_back_wheel" type="continuous">
        <origin rpy="0 0 0" xyz="-0.45 0.28 0" />
        <child link="link_left_back_wheel" />
        <parent link="link_chassis" />
        <axis rpy="0 0 0" xyz="0 1 0" />
        <limit effort="10000" velocity="1000" />
        <joint_properties damping="1.0" friction="1.0" />
    </joint>

    <link name="link_left_back_wheel">
        <inertial>
            <mass value="1" />
            <origin xyz="0 0 0" rpy="0 0 0" />
            <inertia ixx="0.002526666666667" ixy="0" ixz="0" iyy="0.002526666666667" iyz="0" izz="0.005"/>
        </inertial>
        <collision>
            <origin rpy="1.5707 0 0" xyz="0 0.06 0" />
            <geometry>
                <cylinder length="${length_wheel}" radius="${radius_wheel}"/>
            </geometry>
        </collision>
        <visual>
            <origin rpy="1.5707 0 0" xyz="0 0.06 0" />
            <geometry>
                <cylinder length="${length_wheel}" radius="${radius_wheel}"/>
            </geometry>
            <material name="Black">
                <color rgba="0.1 0.1 0.1 1" />
            </material>
        </visual>

        <collision>
            <origin rpy="1.5707 0 0" xyz="0 0.05 0" />
            <geometry>
                <cylinder length="${length_cylinder_wheel}" radius="${radius_cylinder_wheel}"/>
            </geometry>
        </collision>
        <visual>
            <origin rpy="1.5707 0 0" xyz="0 0.05 0" />
            <geometry>
                <cylinder length="${length_cylinder_wheel}" radius="${radius_cylinder_wheel}"/>
            </geometry>
            <material name="Black">
                <color rgba="0.1 0.1 0.1 1" />
            </material>
        </visual>
    </link>

    <joint name="joint_chassis_right_back_wheel" type="continuous">
        <origin rpy="0 0 0" xyz="-0.45 -0.28 0" />
        <child link="link_right_back_wheel" />
        <parent link="link_chassis" />
        <axis rpy="0 0 0" xyz="0 1 0" />
        <limit effort="10000" velocity="1000" />
        <joint_properties damping="1.0" friction="1.0" />
    </joint>

    <link name="link_right_back_wheel">
        <inertial>
            <mass value="1" />
            <origin xyz="0 0 0" rpy="0 0 0" />
            <inertia ixx="0.002526666666667" ixy="0" ixz="0" iyy="0.002526666666667" iyz="0" izz="0.005"/>
        </inertial>
        <collision>
            <origin rpy="1.5707 0 0" xyz="0 -0.06 0" />
            <geometry>
                <cylinder length="${length_wheel}" radius="${radius_wheel}"/>
            </geometry>
        </collision>
        <visual>
            <origin rpy="1.5707 0 0" xyz="0 -0.06 0" />
            <geometry>
                <cylinder length="${length_wheel}" radius="${radius_wheel}"/>
            </geometry>
            <material name="Black">
                <color rgba="0.1 0.1 0.1 1" />
            </material>
        </visual>

        <collision>
            <origin rpy="1.5707 0 0" xyz="0 -0.05 0" />
            <geometry>
                <cylinder length="${length_cylinder_wheel}" radius="${radius_cylinder_wheel}"/>
            </geometry>
        </collision>
        <visual>
            <origin rpy="1.5707 0 0" xyz="0 -0.05 0" />
            <geometry>
                <cylinder length="${length_cylinder_wheel}" radius="${radius_cylinder_wheel}"/>
            </geometry>
            <material name="Black">
                <color rgba="0.1 0.1 0.1 1" />
            </material>
        </visual>
    </link>

    <joint name="joint_chassis_left_front_wheel" type="continuous">
        <origin rpy="0 0 0" xyz="0.45 0.28 0" />
        <child link="link_left_front_wheel" />
        <parent link="link_chassis" />
        <axis rpy="0 0 0" xyz="0 1 0" />
        <limit effort="10000" velocity="1000" />
        <joint_properties damping="1.0" friction="1.0" />
    </joint>

    <link name="link_left_front_wheel">
        <inertial>
            <mass value="1" />
            <origin xyz="0 0 0" rpy="0 0 0" />
            <inertia ixx="0.002526666666667" ixy="0" ixz="0" iyy="0.002526666666667" iyz="0" izz="0.005"/>
        </inertial>
        <collision>
            <origin rpy="1.5707 0 0" xyz="0 0.06 0" />
            <geometry>
                <cylinder length="${length_wheel}" radius="${radius_wheel}"/>
            </geometry>
        </collision>
        <visual>
            <origin rpy="1.5707 0 0" xyz="0 0.06 0" />
            <geometry>
                <cylinder length="${length_wheel}" radius="${radius_wheel}"/>
            </geometry>
            <material name="Black">
                <color rgba="0.1 0.1 0.1 1" />
            </material>
        </visual>

        <collision>
            <origin rpy="1.5707 0 0" xyz="0 0.05 0" />
            <geometry>
                <cylinder length="${length_cylinder_wheel}" radius="${radius_cylinder_wheel}"/>
            </geometry>
        </collision>
        <visual>
            <origin rpy="1.5707 0 0" xyz="0 0.05 0" />
            <geometry>
                <cylinder length="${length_cylinder_wheel}" radius="${radius_cylinder_wheel}"/>
            </geometry>
            <material name="Black">
                <color rgba="0.1 0.1 0.1 1" />
            </material>
        </visual>
    </link>

    <joint name="joint_chassis_right_front_wheel" type="continuous">
        <origin rpy="0 0 0" xyz="0.45 -0.28 0" />
        <child link="link_right_front_wheel" />
        <parent link="link_chassis" />
        <axis rpy="0 0 0" xyz="0 1 0" />
        <limit effort="10000" velocity="1000" />
        <joint_properties damping="1.0" friction="1.0" />
    </joint>

    <link name="link_right_front_wheel">
        <inertial>
            <mass value="1" />
            <origin xyz="0 0 0" rpy="0 0 0" />
            <inertia ixx="0.002526666666667" ixy="0" ixz="0" iyy="0.002526666666667" iyz="0" izz="0.005"/>
        </inertial>
        <collision>
            <origin rpy="1.5707 0 0" xyz="0 -0.06 0" />
            <geometry>
                <cylinder length="${length_wheel}" radius="${radius_wheel}"/>
            </geometry>
        </collision>
        <visual>
            <origin rpy="1.5707 0 0" xyz="0 -0.06 0" />
            <geometry>
                <cylinder length="${length_wheel}" radius="${radius_wheel}"/>
            </geometry>
            <material name="Black">
                <color rgba="0.1 0.1 0.1 1" />
            </material>
        </visual>

        <collision>
            <origin rpy="1.5707 0 0" xyz="0 -0.05 0" />
            <geometry>
                <cylinder length="${length_cylinder_wheel}" radius="${radius_cylinder_wheel}"/>
            </geometry>
        </collision>
        <visual>
            <origin rpy="1.5707 0 0" xyz="0 -0.05 0" />
            <geometry>
                <cylinder length="${length_cylinder_wheel}" radius="${radius_cylinder_wheel}"/>
            </geometry>
            <material name="Black">
                <color rgba="0.1 0.1 0.1 1" />
            </material>
        </visual>
    </link>

    <!-- Laser scan -->
    <joint name="joint_laser_scan_chassis" type="fixed">
        <origin rpy="0 0 0" xyz="0 0 0.16" />
        <child link="link_laser_scan" />
        <parent link="link_chassis" />
        <joint_properties damping="1.0" friction="1.0" />
    </joint>

    <link name="link_laser_scan">
        <inertial>
            <origin xyz="0 0 0" rpy="0 0 0" />
            <mass value="0.5" />
            <inertia ixx="0.000252666666667" ixy="0" ixz="0" iyy="0.000252666666667" iyz="0" izz="0.0005"/>
        </inertial>
        <visual>
            <origin xyz="0 0 0" rpy="0 0 0" />
            <geometry>
                <cylinder radius="0.1" length="0.15"/>
            </geometry>
            <material name="Red">
                <color rgba="0.7 0.1 0.1 1" />
            </material>
        </visual>
        <collision>
            <origin xyz="0 0 0" rpy="0 0 0"/>
            <geometry>
                <cylinder radius="0.1" length="0.15"/>
            </geometry>
        </collision>
    </link>

    <!-- Camera -->
    <joint name="camera_joint" type="fixed">
        <parent link="link_chassis"/>
        <child link="camera_link"/>
        <origin xyz="0.45 0 0.13" rpy="0 0 0"/>
    </joint>

    <link name="camera_link">
        <visual>
            <geometry>
                <box size="0.05 0.05 0.06"/>
            </geometry>
        </visual>
    </link>
</robot>